Workbook
Name ECC_EDC: #REF!
Name Main_MCU_clock_monitor: #REF!
Name MCPS_and_PTS_redudance_verification: #REF!
Name NA: #REF!
Name PTS_Ch1__and__PTS_Ch2__independence_power_supply.: #REF!
Name PWM_fault_detection: #REF!
Name SM_ID: #REF!
Name WhlSpd_sensor_power_supply_diagnosis: #REF!

Sheet 封面
E2: DOCUMENT NO：ABC-T-SW-02.03 文件编号：
A3: SW DFA report 软件DFA报告
B6: Project Nam: 项目名称:
B7: Project ID: 项目ID:
B10: Author: 编制: | D10: Date: 日期: | E10: 2022.08.01
B13: Reviewer: 审核: | D13: Date: 日期: | E13: 2022.08.05
B16: Approver: 批准: | D16: Date: 日期:

Sheet 变更履历
A1: Change History 变更履历
A3: Version 版本 | B3: Status 状态 | C3: Author 编制人 | D3: Date 编制日期 | E3: Approver 批准人 | F3: Approve Date 批准日期 | G3: Description 内容描述
A4: T0 | B4: Draft | D4: 2022.07.01 | G4: 编制初版
A5: A0 | B5: Released | D5: 2022.08.01 | F5: 2022.08.05 | G5: 发布版
A27: “状态”是指文档状态，如：“Draft”, “Released”

Sheet General
A1: General
A2: 1 Document Purpose/文档目的
B3: This document aims at / 本文档旨在: a) identity the dependent failure in SW including the common cause failure and cascading failure; 识别软件中的相关失效，包括共因失效和级联失效； b) evaluate the safety measure to cover the dependent failure; 评估覆盖相关故障的安全措施；
A7: 2 Input Document/输入文档
B8: No. 序号 | C8: Document Name 文档名称 | D8: Version 版本 | E8: Date 日期
B9: 1 | C9: ABC-T-SW-01.01_SW Safety Requirement 软件安全需求规范 | D9: A0 | E9: /
B10: 2 | C10: ABC-T-HW-01.03_HW-SW Interface Specification 软硬件接口规范 | D10: A0 | E10: /
B11: 3 | C11: ABC-T-SW-02.01_SW Architecture Design Specification 软件架构设计规范 | D11: A0 | E11: /
A13: 3 Reference Document/参考文档
B14: No. 序号 | C14: Document Name 文档名称 | D14: Version 版本 | E14: Date 日期
B15: 1 | C15: ABC-G-SW-02.03_SW DFA Guideline | D15: A0 | E15: /
B16: 2 | C16: ISO26262-6 Product development at the software level | D16: Second edition | E16: 2018-12
B17: 3 | C17: ISO26262-9 Automotive safety integrity level (ASIL)-oriented and safety-oriented analyses | D17: Second edition | E17: 2018-12
A20: 4 Terms and Abbreviation/术语和缩略词
B21: No. 序号 | C21: Terms and Abbreviation 术语/缩略词 | D21: description 描述
B22: 1 | C22: SM | D22: security mechanism 安全机制
B23: 2 | C23: DFA | D23: Dependent Failure Analysis 相关失效分析
B24: 3 | C24: CCF | D24: Common CauseFailure 共因失效
B25: 4 | C25: CF | D25: Cascading Failure 级联失效
B26: 5 | C26: DFI | D26: dependent failure initiator 相关失效引发源
B27: 6 | C27: SG | D27: safety goal 安全目标

Sheet SW architecture
A1: static architecture
A3: 1 Introduction of Product
B4: SRQ_001 | C4: 这是基于ABC项目的整车控制系统。
B5: SRQ_002 | C5: 本规范定义了项目的软件需求。
A6: 初始的静态架构图（SWC）
A31: Dynamic Architecture
A32: 数据流引用到这里，数据流要有信号名称体现

Sheet Combination matrix
C2: Vin01 | D2: swc2 | E2: IN-HALL
C3: ASIL X/QM | D3: ASIL X | E3: ASIL X
A4: Vin01 | B4: ASIL X/QM | C4: SW_DF_003 | D4: SW_DF_001
A5: swc2 | B5: ASIL X | C5: SW_DF_002 | H5: ASIL D | J5: S1(QM）
H6: VIN01 | J6: S2（ASIL D)

Sheet Top Event
B1: DFA Top Event From FFI/Independent
B2: "I":Independce. [ISO26262-9-2018] Freedom from interference and absence of common cause failures are used to justify independence when performing ASIL decomposition "F":Freedom from interference. [ISO26262-9-2018] Freedom from interference is used to justify the coexistence of elements with different, or no, assigned ASIL. "O": No need to disguss.
B3: Top EventID | C3: Event Description | D3: Function Description | E3: ASIL | F3: common cause failure ? | G3: cascading failure ? | H3: ﻿coexistence- Freedom from interface? | I3: — similar and dissimilar redundant elements; (功能冗余，分解) | J3: — ASIL decomposition（分解） | K3: — different functions implemented with identical software or hardware elements;(同一个集成模块） | L3: — functions and their respective safety mechanisms;（分解） | M3: — partitions of functions or software elements;(QM, ASIL FFI) | N3: — physical distance between hardware elements, with or without a barrier; and | O3: — common external resources.（按照最高等级开发）
B4: SW_DF_001 | C4: SWC1: SWC2 & SWC3 | D4: SWC2 FUNCTION & SWC3 FUNCTION | E4: D(D) & QM(D) | F4: Y | L4: Y
B5: SW_DF_002
B6: SW_DF_003 | C6: VIN01: S1&S2&S3&

Sheet SW DFA
A1: SW DFA
A3: ='Top Event'!B4 -> SW_DF_001 | C3: ='Top Event'!C4 -> SWC1: SWC2 & SWC3 | D3: ='Top Event'!D4 -> SWC2 FUNCTION & SWC3 FUNCTION | E3: ='Top Event'!E4 -> D(D) & QM(D)
B4: 公式格式，误删 | C4: DF-I Category | D4: Interpretation | E4: DF-Initiator Examples | F4: Applicable? | G4: safety goal related | H4: Counter Measure | I4: Counter Measure ID | J4: Evidence | K4: sufficient? | L4: Comment
A5: =A3&"_"&B5 -> SW_DF_001_1 | B5: 1 | C5: Shared resource | D5: The same software, hardware, or system element instance used by the two elements which are therefore affected by the failure or unavailability of that shared resource, i.e. from a physical perspective. | E5: Software component used by more than one other software component, e.g. – reused standard software modules | F5: not applicable
A6: =A3&"_"&B6 -> SW_DF_001_2 | B6: 2 | E6: – libraries | F6: Yes : 来源于同一个AFE lib | G6: LIB 错误， 传递给SWC1和SWC2 错误数据， 造成计算错误的灯光命令， 违背安全目标SG01 | H6: AFE LIB SWC 满足ASIL C[按照最高等级开发] | I6: SW_DFA_SM_001: | J6: 通过ASIL C测试 | K6: AFE LIB SWC 满足ASIL C 开发和测试
A7: =A3&"_"&B7 -> SW_DF_001_3 | B7: 3 | E7: – middleware
A8: =A3&"_"&B8 -> SW_DF_001_4 | B8: 4 | E8: – basic software
A9: =A3&"_"&B9 -> SW_DF_001_5 | B9: 5 | E9: – operating system including scheduler
A10: =A3&"_"&B10 -> SW_DF_001_6 | B10: 6 | E10: – communication stack
A11: =A3&"_"&B11 -> SW_DF_001_7 | B11: 7 | E11: – parameter file
A12: =A3&"_"&B12 -> SW_DF_001_8 | B12: 8 | E12: – execution time
A13: =A3&"_"&B13 -> SW_DF_001_9 | B13: 9 | E13: – allocated memory
A14: =A3&"_"&B14 -> SW_DF_001_10 | B14: 10 | C14: Components of identical type | D14: Identical components may fail with higher probability simultaneously (common mode failures) | E14: • Reused standard software modules
A15: =A3&"_"&B15 -> SW_DF_001_11 | B15: 11 | E15: • Standard library components
A16: =A3&"_"&B16 -> SW_DF_001_12 | B16: 12 | E16: • Middleware
A17: =A3&"_"&B17 -> SW_DF_001_13 | B17: 13 | E17: • Operating system
A18: =A3&"_"&B18 -> SW_DF_001_14 | B18: 14 | E18: • Communication stack
A19: =A3&"_"&B19 -> SW_DF_001_15 | B19: 15 | E19: • Parameter set
A20: =A3&"_"&B20 -> SW_DF_001_16 | B20: 16 | C20: Communication between the two functions | D20: Receiving function is affected by information that is false, lost, sent multiple times, or in the wrong order etc. from the sender | E20: • Information passed via argument through a function call, or via writing/reading a variable being global to the two software functions (data flow)
A21: =A3&"_"&B21 -> SW_DF_001_17 | B21: 17 | E21: • Data or message corruption/ repetition*/ loss*/ delay*/ masquerading or incorrect addressing of information*
A22: =A3&"_"&B22 -> SW_DF_001_18 | B22: 18 | E22: • Insertion*/ sequence of information*
A23: =A3&"_"&B23 -> SW_DF_001_19 | B23: 19 | E23: • Corruption of information*
A24: =A3&"_"&B24 -> SW_DF_001_20 | B24: 20 | E24: • Asymmetric information sent from a sender to multiple receivers*
A25: =A3&"_"&B25 -> SW_DF_001_21 | B25: 21 | E25: • Information from a sender received by only a subset of the receivers*
A26: =A3&"_"&B26 -> SW_DF_001_22 | B26: 22 | E26: • Blocking access to a communication channel*
A27: =A3&"_"&B27 -> SW_DF_001_23 | B27: 23 | C27: Shared information inputs | D27: Same information consumed by the two functions even in absence of shared resources, i.e. from a functional perspective | E27: • Calibration parameters
A28: =A3&"_"&B28 -> SW_DF_001_24 | B28: 24 | E28: • Constants, or variables, being global to the two software functions
A29: =A3&"_"&B29 -> SW_DF_001_25 | B29: 25 | E29: • Basic software passes data (read from hardware register and converted into logical information) to two application software functions
A30: =A3&"_"&B30 -> SW_DF_001_26 | B30: 26 | E30: • Data / function parameter arguments / messages delivered by software function to more than one other function See also “Communication between the two functions”
A31: =A3&"_"&B31 -> SW_DF_001_27 | B31: 27 | C31: Environmental influences | D31: Common external environmental disturbance affects both functions | E31: System-level: mechanical shock, water ingress
A32: =A3&"_"&B32 -> SW_DF_001_28 | B32: 28 | E32: Software-level: not applicable for Software
A33: =A3&"_"&B33 -> SW_DF_001_29 | B33: 29 | E33: Hardware-level: under and over voltage of the power supply
A34: =A3&"_"&B34 -> SW_DF_001_30 | B34: 30 | C34: Unintended impact | D34: Two functions affecting each other’s elements directly via an implicit, that is unintended interface. | E34: • Memory / corruption of content* – “wild pointers“ (including program counter stack)
A35: =A3&"_"&B35 -> SW_DF_001_31 | B35: 31 | E35: – memory mis-allocation
A36: =A3&"_"&B36 -> SW_DF_001_32 | B36: 32 | E36: – memory leaks
A37: =A3&"_"&B37 -> SW_DF_001_33 | B37: 33 | E37: – read/write access to memory allocated to another software element*
A38: =A3&"_"&B38 -> SW_DF_001_34 | B38: 34 | E38: – buffer under-/overflow
A39: =A3&"_"&B39 -> SW_DF_001_35 | B39: 35 | E39: • Timing and execution – deadlocks*
A40: =A3&"_"&B40 -> SW_DF_001_36 | B40: 36 | E40: – livelocks*
A41: =A3&"_"&B41 -> SW_DF_001_37 | B41: 37 | E41: – incorrect allocation of execution time*
...

Sheet SM list
A1: Safety measure list
A2: ID | B2: Safety Mechanism Description | C2: SSR ID | D2: ASIL | E2: Allocation | F2: DC | G2: sufficient | H2: SG1
A3: SG01_DFA_SM_01 | B3: When WDT-SWC monitor the time_task deviation is over [10ms],shall reset the time_task 当WDT-SWC监测到时间任务偏差超过[10ms]时，应重置时间任务 | C3: SSR_00x | E3: SWC -XX | F3: HIGH | G3: yes -
A4: SG01_DFA_SM_02 | B4: When the RAM-SWC monitor the RAM fault, shall reset the RAM within [10ms] 当RAM-SWC监测到RAM故障时，应在[10ms]内重置RAM | C4: SSR_00x
A5: SG02_DFA_SM_01 | B5: 当电源电压检测-SWC模块检测到电压超过32V后，10ms内切断供电电源 | C5: SSR_00x
A6: SG03_DFA_SM_01 | B6: 当执行时间分配错误时，将执行时间重新分配，该执行时间作为标定量 | C6: SSR_00x

Sheet example
A2: Interaction ID | B2: Interaction Description | C2: DF-I Category | D2: Interpretation | E2: DF-Initiator | F2: Applicable? | G2: Failure effect for SG1 | H2: independent? | I2: SM_ID | J2: Counter Measure Description | K2: Evidence | L2: Sufficient? | M2: Comment
A3: SW_DFA_1_5_7 - "OS" And "WdgM" NO Cascading Failure and NO Common Cause Failure
A4: SW_DFA_1_5_7 | B4: "OS" And "WdgM" NO Cascading Failure and NO Common Cause Failure | C4: Shared resource | D4: The same software, hardware, or system element instance used by the two elements which are therefore affected by the failure or unavailability of that shared resource, i.e. from a physical perspective. | E4: ◆ Software component used by more than one other software component, e.g 1) reused standard software modules | F4: NA | G4: NA
E5: 2) libraries | F5: NA | G5: NA
E6: 3) middleware | F6: NA | G6: NA
E7: 4) basic software | F7: NA | G7: NA
E8: 5) operating system including scheduler | F8: Y | G8: Y | J8: Monitor scheduler fault | K8: Refer to SSR-19-1 SSR-19-2 SSR-19-3 | L8: Y
E9: 6) communication stack | F9: NA | G9: NA
E10: 7) parameter file | F10: Y | G10: Y | J10: Check configuration paramater fault | K10: Refer to SSR-18-1 | L10: Y
E11: 8) execution time | F11: NA | G11: NA | J11: Monitor component runnable execution time, avoid dead lock and overtime | K11: Refer to SSR-19-1 SSR-19-2 SSR-19-3 | L11: Y
E12: 9) allocated memory | F12: Y | G12: Y | J12: Implement MPU Or develop according to higher ASIL | K12: Refer to SSR-13-1 | L12: Y
C13: Components of identical type | D13: Identical components may fail with higher probability simultaneously (common mode failures). | E13: ◆ Reused standard software modules | F13: NA | G13: NA
E14: ◆ Standard library components | F14: NA | G14: NA
E15: ◆ Middleware | F15: NA | G15: NA
E16: ◆ Operating system | F16: Y | G16: Y | H16: OS | J16: Monitor scheduler fault | K16: Refer to SSR-19-1 SSR-19-2 SSR-19-3 | L16: Y
E17: ◆ Communication stack | F17: NA | G17: NA
E18: ◆ Parameter set | F18: NA | G18: NA
C19: Communication between the two functions | D19: Receiving function is affected by information that is false, lost, sent multiple times, or in the wrong order etc. from the sender | E19: ◆ Information passed via argument through a function call, or via writing/reading a variable being global to the two software functions (data flow) | F19: NA | G19: NA
E20: ◆ Data or message corruption/ repetition*/ loss*/ delay*/ masquerading or incorrect addressing of information* | F20: Y | G20: Y | H20: BSW and ASW communication by RTE with E2E protection | J20: SW_DFA_10 | K20: Autosar RTE | L20: yes,AUTOSAR certificate
E21: ◆ Insertion*/ sequence of information* | F21: Y | G21: Y | H21: 一般是通讯相关的有，比如RTE 传递的都有， | J21: RTE transferred messsage shall protection E2E
E22: ◆ Corruption of information* | F22: Y | G22: Y | H22: RTE | J22: RTE transferred messsage shall protection E2E
E23: ◆ Asymmetric information sent from a sender to multiple receivers* | F23: Y | G23: Y | H23: RTE | J23: RTE transferred messsage shall protection E2E
E24: ◆ Information from a sender received by only a subset of the receivers* | F24: Y | G24: Y | H24: RTE | J24: RTE transferred messsage shall protection E2E
E25: ◆ Blocking access to a communication channel* | F25: Y | G25: Y | H25: RTE | J25: RTE transferred messsage shall protection E2E
C26: Shared information inputs | D26: Same information consumed by the two functions even in absence of shared resources, i.e. from a functional perspective | E26: ◆ Calibration parameters | F26: Y | G26: Y | H26: RTE | J26: Check configuration paramater fault | K26: Refer to SSR-18-1 | L26: Y
E27: ◆ Constants, or variables, being global to the two software functions | F27: Y | G27: Y | H27: RTE | J27: Check configuration paramater fault | K27: Refer to SSR-18-x | L27: Y
E28: ◆ Basic software passes data (read from hardware register and converted into logical information) to two application software functions | F28: NA | G28: NA | H28: 一般底层的都有
E29: ◆ Data / function parameter arguments / messages delivered by software function to more than one other function See also “Communication between the two functions” | F29: NA | G29: NA
C30: Environmental influences | D30: Common external environmental disturbance affects both functions | E30: ◆ System-level: mechanical shock, water ingress | F30: NA | G30: NA
E31: ◆ Software-level: not applicable for Software | F31: NA | G31: NA
E32: ◆ Hardware-level: under and over voltage of the power supply | F32: NA | G32: NA
C33: Unintended impact | D33: Two functions affecting each other’s elements directly via an implicit, that is unintended interface. | E33: ◆ Memory / corruption of content* 1) “wild pointers“ (including program counter stack) | F33: Y | G33: Y | J33: ECC and EDC check RAM and Flash fault | K33: Refer to SSR-13-1 | L33: Y
E34: 2) memory mis-allocation | F34: Y | G34: Y | H34: Check memory allocation fault.
E35: 3) memory leaks | F35: NA | G35: NA | H35: Do not use dynamic memory allocation, except OS，如果用需要 | J35: Monitor OS stack fault | K35: Refer to SSR-13-1 | L35: Y
E36: 4) read/write access to memory allocated to another software element* | F36: Y | G36: Y | J36: Implement MPU | K36: Refer to SSR-13-1 | L36: Y
E37: 5) buffer under-/overflow | F37: Y | G37: Y | J37: Implement MPU on task stack Or monitor task stack | K37: Refer to SSR-13-1 | L37: Y
E38: ◆ Timing and execution 1) deadlocks* | F38: Y | G38: Y | H38: Static and dynamic check running fault. | J38: Implement QA window watchdog to monitor task running. | K38: Refer to SSR-19-1 SSR-19-2 SSR-19-3 | L38: Y
E39: 2) livelocks* | F39: Y | G39: Y | H39: Static and dynamic check running fault. | J39: Implement QA window watchdog to monitor task running. | K39: Refer to SSR-19-1 SSR-19-2 SSR-19-3 | L39: Y
E40: 3) incorrect allocation of execution time* | F40: Y | G40: Y | H40: Static and dynamic check running fault. | J40: Implement QA window watchdog to monitor task running. | K40: Refer to SSR-19-1 SSR-19-2 SSR-19-3 | L40: Y
E41: 4) incorrect synchronization between software elements* | F41: Y | G41: Y | H41: Static and dynamic check running fault. | J41: Implement QA window watchdog to monitor task running. | K41: Refer to SSR-19-1 SSR-19-2 SSR-19-3 | L41: Y
...

Sheet 模板变更履历
A1: Template Change History 模板变更履历
A3: Version 版本 | B3: Status 状态 | C3: Author 编制人 | D3: Date 编制日期 | E3: Approver 批准人 | F3: Approve Date 批准日期 | G3: Description 内容描述
A4: T0 | B4: Draft | D4: 2022.07.01 | G4: 编制初版
A5: A0 | B5: Released | D5: 2022.08.01 | F5: 2022.08.05 | G5: 发布版
A27: “状态”是指文档状态，如：“Draft”, “Released”
