Workbook
Name DocStatus: [1]data!$B$2:$B$8
Name Projektmitarbeiter: '1_Role and Responsibilities'!$E$19:$H$32
Name Status: Tabelle1!$A$2:$A$10

Sheet Cover
B1: Safety Plan
D2: Version
D4: Date
D6: Status
A7: Project
A11: 1. Participants
A12: Last Name, First Name | B12: Job Titile | C12: Role | E12: Responsible For
A25: 2. Quality Assurance
A26: Role | B26: Name | C26: Date | E26: Status
A27: Reviewer
A28: Approver
A32: 3. Change Record
A33: Document Section | B33: Change Description | D33: Version | E33: Date | F33: Author

Sheet General-Description
A1: =Cover!B1 -> Safety Plan
A2: 1 Introducion
A3: This template "safety plan" includes all document relevant aspects of ISO 26262. By listing the work products, the distribution of responsibilty and appointments and allocating the status, the project can effectively be setup and be tracked. At the same time the key aspects (see Figure 2 Scope of the Safety Plan) of a "DIA" and a "Safety Cases" are satisfiable. (Relevant information and input into the template provided) For the user this also offers an easy way to customize the template according to his needs. Columns and rows can be added. By using "cross-references" a parallel description with all the negative effects is avoided. Main intention is keeping key information by collecting the appropriate links and to give/collect/track status and time line.
A4: 2 Scope of the Safety Plan
A5: The safety manager shall maintain the "Safety Plan", and monitor the progress of the safety activities against the safety plan. The aspects of a "Development Interface Agreement" (DIA) is the definition and description of the flow of all safety related development activities and work products. It shall define the interfaces between OEM and Suppliers for distributed development projects. The "Safety Case" should progressively compile the work products that are generated during the safety lifecycle. All three aspects can be combined with these work sheets and their inclosing work products.
A6: 3 Structure of the document:
A7: 1. Sheet "1_Role and Responsibilities": All involved persons and companies and roles in the project are listet and are referenced in the other sheets. 2. Sheet "2_Safety_plan": The general planing of the project is done within these sheet. A detailed description of the single rows can be found in the sheet "Description of 2_Safety_plan" 3. Sheet "3_Document_list": This is the list where all the document and work products are listed and the refering Verknäpfungen within the project are done. A detailed description of the single rows can be found in the sheet "Description of 3_Document_list" 4. Sheet "DATA": Within this sheet there are needed excel datas stored.
A8: 4 General description hints to used bakground colors:
A9: All cells filled with grey are not to be filled out
A10: All cells filled with yellow are not to be filled out
A11: All cells filled with linked content
A12: All cells Partly filled with blue are not to be filled out
A13: All cells filled with white color are to be filled
... A15: ASIL = Automotive Safety Integrity Level OU = Organisation Unit SaM = Safety Manager SaE = Safety Engineer PL = Project leader SPL = Subproject Leader R1)A2)S3)C4)I5) = Responsible, Accountable, Support, Consultant, Informative FMEA = Failure Mode & Effect Analysis FTA = Fault Tree Analysis HAZOP = Hazard and Operability study ETA = Event Tree Analysis RBD = Reliability Block Diagram

Sheet 1_Role and Responsibilities
A1: =Cover!B1 -> Safety Plan
A2: Project Milestones
A4: Planning and Coordination of Safety Activities
A5: Refer to Safety plan Sheet
A7: Organization Chart
A9: Escalation Path
A11: Comunication Mechanism
A13: Problem Management
A15: Supporting Process
A17: Assignment of roles / persons
A18: No. | B18: Role | C18: Organization | D18: Title in Project | E18: Responsibility | I18: Name | J18: Qualification | K18: Contact details
A19: 1 | B19: Project Manager (Item) | C19: OEM | D19: =C19 & " " & B19 -> OEM Project Manager (Item) | K19: Phone: Mobile: Fax: E-Mail:
A20: =A19+1 -> 2 | B20: Safety Manager (Item) | C20: OEM | D20: =C20 & " " & B20 -> OEM Safety Manager (Item) | K20: Phone: Mobile: Fax: E-Mail:
A21: =A20+1 -> 3 | B21: Project Director | C21: OEM | D21: =C21 & " " & B21 -> OEM Project Director | K21: Phone: Mobile: Fax: E-Mail:
A22: =A21+1 -> 4 | B22: Project Manager (ECU) | C22: Tier 1 Supplier | D22: =C22 & " " & B22 -> Tier 1 Supplier Project Manager (ECU) | K22: Phone: Mobile: Fax: E-Mail:
A23: =A22+1 -> 5 | B23: Safety Manager (ECU) | C23: Tier 1 Supplier | D23: =C23 & " " & B23 -> Tier 1 Supplier Safety Manager (ECU) | K23: Phone: Mobile: Fax: E-Mail:
A24: =A23+1 -> 6 | B24: Quality Manager (ECU) | C24: Tier 1 Supplier | D24: =C24 & " " & B24 -> Tier 1 Supplier Quality Manager (ECU) | K24: Phone: Mobile: Fax: E-Mail:
A25: =A24+1 -> 7 | B25: R&D Manager (ECU) | C25: Tier 1 Supplier | D25: =C25 & " " & B25 -> Tier 1 Supplier R&D Manager (ECU) | K25: Phone: Mobile: Fax: E-Mail:
A26: =A25+1 -> 8 | B26: Safety Expert (ECU) (System) | C26: Tier 1 Supplier | D26: =C26 & " " & B26 -> Tier 1 Supplier Safety Expert (ECU) (System) | K26: Phone: Mobile: Fax: E-Mail:
A27: =A26+1 -> 9 | B27: Safety Expert (ECU) (HW + HW-Test) | C27: Tier 1 Supplier | D27: =C27 & " " & B27 -> Tier 1 Supplier Safety Expert (ECU) (HW + HW-Test) | K27: Phone: Mobile: Fax: E-Mail:
A28: =A27+1 -> 10 | B28: Safety Expert (ECU) (SW + SW-Test, Tool-Qualification) | C28: Tier 1 Supplier | D28: =C28 & " " & B28 -> Tier 1 Supplier Safety Expert (ECU) (SW + SW-Test, Tool-Qualification) | K28: Phone: Mobile: Fax: E-Mail:
A29: =A28+1 -> 11 | B29: Safety Expert (ECU) (Safety Analyses, HW-Metrics) | C29: Tier 1 Supplier | D29: =C29 & " " & B29 -> Tier 1 Supplier Safety Expert (ECU) (Safety Analyses, HW-Metrics) | K29: Phone: Mobile: Fax: E-Mail:
A30: =A29+1 -> 12 | B30: Configuration Manager | D30: =C30 & " " & B30 -> Configuration Manager | K30: Phone: Mobile: Fax: E-Mail:
A31: =A30+1 -> 13 | B31: Project Director | D31: =C31 & " " & B31 -> Project Director | K31: Phone: Mobile: Fax: E-Mail:
A32: =A31+1 -> 14 | B32: Safety Assessor (ECU) | D32: =C32 & " " & B32 -> Safety Assessor (ECU) | K32: Phone: Mobile: Fax: E-Mail:
A34: Change Histroy
A35: No. | B35: Description | C35: Author | G35: Date | I35: Version
A36: 1
A37: 2
A38: 3
A39: 4
A41: References
A42: No. | B42: Description | C42: Author | G42: Date | I42: Version
A43: 1
A44: 2
A45: 3
A46: 4
A47: 5

Sheet Description of 2_Safety_plan
A1: =Cover!B1 -> Safety Plan
A2: 1. Description to headlines of sheet "2_Safety_plan"
A3: No. | B3: Number of List
A4: Reference to standard | B4: The refering chapter number of ISO26262
A6: Content | B6: Summarized content description. Partly filled with examples.
A7: Objectives / Target | B7: Condensed description of each objectiv/target.The content describes the requirements of the ISO 26262 standard. For the particular development project supplements or descriptions can be to added below.
A8: Implementation of Objectives /Targets | B8: Description and hints of the implementation in the project. Partly filled with examples.
A9: Input documents | B9: Document content, prerequisities or results which are needed as input information.
A10: Output documents | B10: Documents content or results which areoutput information Partly filled with examples.
A11: Responsibility | B11: The responsible for the Output document. For first approach as minimum information the resp. organisation has to be stated. There might be more than one. Partly filled with examples.
A12: Implementation accomplishment | B12: As far as the implementation differes from the responsible organisation it has to be stated by whom the Implementation/accomplishment relies on. There might be more than one named thus these can be named by adding rows. Partly filled with examples.
A13: Start | B13: Planed start of the activity in accordance of the roject plan. Partly filled with examples.
A14: End | B14: Planed End of the activity in accordance of the roject plan. Partly filled with examples.
A15: Resources [h] | B15: If appilcable Estimated working hours for Output Partly filled with examples.
A16: Note | B16: Space for notes. Partly filled with examples.

Sheet 2_Safety_plan
A1: =[2]Cover!B3 -> Safety Plan
F2: =[2]Cover!$B$7 -> Project: ECU
AB3: =#REF! -> #REF!
AB4: =#REF! -> #REF! | AC4: =#REF! -> #REF!
AB5: ='1_Role and Responsibilities'!#REF! -> #REF!
AB6: ='1_Role and Responsibilities'!#REF! -> #REF!
A7: No. | B7: Reference to standard | C7: Content | D7: Objectives / Target | E7: Implementation of Objectives /Targets | F7: Mapping to Internal Work Product | G7: Tailoring applicable? | H7: Arguments for applying the Tailoring [see 26262-8 Support] | I7: Input documents | J7: Output documents | K7: Responsibility | L7: Implementation accomplishment | M7: Start | N7: End | O7: ='1_Role and Responsibilities'!$D22 -> Tier 1 Supplier Project Manager (ECU) | P7: ='1_Role and Responsibilities'!$D23 -> Tier 1 Supplier Safety Manager (ECU) | Q7: ='1_Role and Responsibilities'!$D24 -> Tier 1 Supplier Quality Manager (ECU) | R7: ='1_Role and Responsibilities'!$D25 -> Tier 1 Supplier R&D Manager (ECU) | S7: ='1_Role and Responsibilities'!$D26 -> Tier 1 Supplier Safety Expert (ECU) (System) | T7: ='1_Role and Responsibilities'!$D27 -> Tier 1 Supplier Safety Expert (ECU) (HW + HW-Test) | U7: ='1_Role and Responsibilities'!$D28 -> Tier 1 Supplier Safety Expert (ECU) (SW + SW-Test, Tool-Qualification) | V7: ='1_Role and Responsibilities'!$D29 -> Tier 1 Supplier Safety Expert (ECU) (Safety Analyses, HW-Metrics) | W7: ='1_Role and Responsibilities'!$D32 -> Safety Assessor (ECU) | X7: Development Resources [h] | Y7: Safety Assessor Resource [h] | Z7: Gesamt Resources [h] | AA7: Resource to Use | AB7: Note | AC7: Date of Note
A9: 1 | C9: General
C10: Purpose | D10: The requirements of the ISO 26262 safety standard lead to the necessity of systematically planning the activities and measures for ensuring functional safety and of naming responsible persons for the individual activities. This is part of the management tasks of the person responsible for the entire project.
C11: Procedure | D11: The safety project plan serves to systematically plan and allocate the safety activities required and the resources necessary for its implementation. The safety plan on hand was adapted to the project. This plan is to be approved by the project management; the safety activities are to be explicitly adopted into the overall project plan in sufficient detail and the necessary resources are to be assigned to them. The safety project plan is implemented, versioned and archived for future reference by the project management. Updates and adjustments of the safety plan are also subject to versioning and documentation as in a controlled document. The updated safety project plan forms the basis for the creation of what is referred to as “safety cases”, a systematic summary of all documents necessary for proving functional safety.
A12: 2 | B12: ISO 26262-2 | C12: Management of functional safety
B13: ISO 26262-2 Clause 5 | C13: Management of functional safety - Overall safety management
A14: 2.1 | B14: ISO 26262-2, 5.5.1 | C14: Organization-specific rules and processes for functional safety | D14: Objective acc. the standard ISO 26262-2 (clause: 5.4.2.2): The organization shall institute, execute and maintain organization-specific rules and processes to comply with the requirements of ISO 26262. NOTE Such organization-specific rules and processes can include the creation and maintenance of a generic safety plan and process description. | E14: e.g. generic process of functional saftey | J14: Organization-specific rules and processes for functional safety | K14: OEM Project Manager (Item) | L14: OEM Project Director
A17: 2.2 | B17: ISO 26262-2, 5.5.2 | C17: Evidence of competence | D17: Objective acc. the standard ISO 26262-2 (clause 5.4.3.1): The organization shall ensure that the persons involved in the execution of the safety lifecycle have a sufficient level of skills, competences and qualifications corresponding to their responsibilities. (Knowledge in safety technology, safety standards, etc.) | E17: Client's safety management training program, etc. ETSS analysis results, training certificate, Client qualification, office organization, etc. | G17: No | J17: Evidence of competence
A20: 2.3 | B20: ISO 26262-2, 5.5.3 | C20: Evidence of quality management | D20: Objective acc. the standard ISO 26262-2 (clause 5.4.4.1): The organizations involved in the execution of the safety lifecycle shall have an operational quality management system complying with a quality management standard, such as ISO/TS 16949, ISO 9001, or equivalent. | E20: See Project Plan | G20: No | I20: ISO 9001 certificate, ISO TS 16949 certificate, Audit reports, | J20: Evidence of quality management | AB20: ISO 16949
A23: 2.3 | B23: ISO 26262-2, 5.5.4 | C23: Identified safety anomaly | D23: Objective acc. the standard ISO 26262-2 (clause 5.4.3): | G23: No | I23: Safety anomaly | J23: Identified Safety anomaly report | AB23: ISO 16949
B26: ISO 26262-2 Clause 6 | C26: Management of functional safety - Safety management during the concept phase and the product development
A27: 2.4 | B27: ISO 26262-2, 6.5.1,6.5.2 | C27: Impact Analysis | D27: Objective acc. the standard ISO 26262-2 (clause 6.4.3 and clause 6.4.4) | G27: No | I27: Customer Project Requirements or Internal Project Requirements | J27: Impact Analysis Report
A30: 2.5 | B30: ISO 26262-2, 6.5.3 | C30: Safety plan | D30: Objective acc. the standard ISO 26262-2 (clause 6.4.3.4): The safety plan shall either be a) referenced in the project plan, or b) included in the project plan, such that the safety activities are distinguishable Objective for Item under developement: Project management for the safety activities • Planning of safety activities with regard to time and resources • Defining responsibilities • Requesting the results of the work packages defined in the safety plan from those responsible in a timely manner • Updating the safety plan with regard to changes in dates, resources, work packages • Determining the safety-relevant release stECU up to series launch | G30: No | I30: Project plan, System concept draft, System concept review, DIA, Timeline with milestones for prototypes, Required documents according to ISO26262 | J30: Safety Plan
A33: 2.6 | B33: ISO 26262-2, 6.5.4 | C33: Safety Case | D33: Objective acc. the standard ISO 26262-2: (clause 6.4.6.1) This requirement shall be complied with for items that have at least one safety goal with an ASIL (A), B, C or D: a safety case shall be developed in accordance with the safety plan. (clause 6.4.6.2) The safety case should progressively compile the work products that are generated during the safety lifecycle. | G33: No | I33: Document list, Available work products, protocols, meeting minutes... | J33: Safety Case
A36: 2.7 | B36: ISO 26262-2, 6.5.5 | C36: Functional safety assessment plan | D36: Objective acc. the standard ISO 26262-2: (clause 6.4.9.1) A functional safety assessment shall be carried out for items, where the highest ASIL of the item's safety goals is ASIL (B), C, or D. (clause 6.4.9.2) A functional safety assessment shall be planned in accordance with 6.4.3.3 and 6.4.3.5 i). EXAMPLE Agenda for a functional safety assessment given in Annex E. | G36: No | I36: Work products required by the safety plan; safety processes; | J36: Functional safety assessment plan
A39: 2.8 | B39: ISO 26262-2, 6.5.5 | C39: Confirmation measure reports | D39: Objective acc. the standard ISO 26262-2: (clause 6.4.7.1) The confirmation measures specified in Table 1, ISO 26262-2 shall be performed, in accordance with the required level of independency. Remark: A confirmation review includes the checking of correctness with respect to formality, contents, adequacy and completeness regarding the requirements of ISO 26262. ONLY Organization and planning of confirmation reviews | G39: No | I39: Table of confirmation measures, Assessment report, Audit report | J39: Confirmation measures reports
A42: 2.9 | B42: ISO 26262-2, 6.5.6 | C42: Release for production report | D42: Objective acc. the standard ISO 26262-2(clause 6.4.13) The requirements of ISO 26262-2, clause 6.4.13 shall be fulfilled. The objective of this clause is to specify the release for production criteria at the completion of the item development. The release for production confirms that the item complies with the requirements for functional safety at the vehicle level. | E42: Tier1 shall state the release for production in order to confirm that the item complies with the requirements for functional safety. | G42: No | I42: Safety plan, Safety case, Project Plan, | J42: Release for production report
B45: ISO 26262-2 Clause 7 | C45: Management of functional safety - Safety management after the item's release for production
A46: 2.10 | B46: ISO 26262-2, 7.5.1 | C46: Evidence of safety management regarding production, operation, service and decommissioning | D46: Objective acc. the standard ISO 26262-2: (clause 7.4.2): The objective of this clause is to define the responsibilities of the organizations and persons responsible for functional safety after the item's release for production. This relates to the general activities for ensuring the required functional safety of the item during the lifecycle sub phases after the release for production. | G46: No | I46: Evidence of quality management | J46: Suppliers Safety Management and support processes after SOP
A49: 3 | B49: ISO 26262-3
B50: ISO 26262-3 Clause 5 | C50: Item definition
A51: 3.1 | B51: ISO 26262-3, 5.5.1 | C51: Item definition | D51: Objective acc. the standard ISO 26262-3(clause 5.5.1): The first objective is to define and describe the item, its dependencies on, and interaction with, the environment and other items. The second objective is to support an adequate understanding of the item so that the activities in subsequent phases can be performed. Remark: Description of planed function. On the basis of a represented system design a project order could be released. | E51: A description of the item with the corresponding subsystems XYZ: e.g.: steering angle sensor, torque sensor of steering wheel , Shift by wire shall be prepared. | G51: No | I51: System concept draft, System concept review, Item definition | J51: Item definition
H52: =IF(#REF!="","",#REF!) -> #REF!
B54: ISO 26262-3 Clause 6 | C54: Hazard analysis and risk assessment (System and subsystem)
A55: 3.2 | B55: ISO 26262-3, 6.5.1 | C55: Hazard analysis and risk assessment | D55: Objective acc. the standard ISO 26262-3: The objective of the hazard analysis and risk assessment is to identify and to categorise the hazards that malfunctions in the item can trigger and to formulate the safety goals related to the prevention or mitigation of the hazardous events, in order to avoid unreasonable risk. | G55: No | I55: Existing H&R, Item definition Impact analysis, Relevant information of other subsystems, | J55: Hazard analysis and risk assessment
A58: 3.3 | B58: ISO 26262-3, 6.5.2 | C58: Safety goals | D58: Objective acc. the standard ISO 26262-3: A safety goal shall be determined for each hazardous event with an ASIL evaluated in the hazard analysis. | E58: The existing safety goals shall be checked by Tier1 / Independent Reviewer. | G58: No | I58: Existing safety goals, | J58: Safety goals
A61: 3.4 | B61: ISO 26262-3, 6.5.3 | C61: Verification report of the hazard analysis and risk assessment and the safety goals. | D61: Objective acc. the standard ISO 26262-3: The hazard analysis, risk assessment and the safety goals shall be verified in accordance with ISO 26262-8:2018, Clause 9, to show their: a) completeness with regard to situations and hazards; b) compliance with the item definition; c) consistency with related hazard analyses and risk assessments; d) completeness of the coverage of the hazardous events; and e) consistency of the assigned ASILs with the corresponding hazardous events. | G61: No | I61: Existing review report of the Hazard analysis and risk assessment and the safety goals. | J61: Verification review report of the hazard analysis and risk assessment and the safety goals.
B64: ISO 26262-3 Clause 7 | C64: Functional safety concept
A65: 3.5 | B65: ISO 26262-3, 7.5.1 | C65: Functional safety concept | D65: Objective acc. the standard ISO 26262-3: The objective of the functional safety concept is to derive the functional safety requirements, from the safety goals, and to allocate them to the preliminary architectural elements of the item, or to external measures. | G65: No | I65: Item definition H&R, Safety goals, Technik Komponenten Lastenheft, SANF_Sicherheitsanforderungen | J65: Functional safety concept (including safety architecture)
A68: 3.6 | B68: ISO 26262-3, 7.5.2 | C68: Verification report of the functional safety concept | D68: Objective acc. the standard ISO 26262-3: The functional safety concept shall be verified in accordance with ISO 26262-8:2018, Clause 9, to show a) its consistency and compliance with the safety goals; and b) its ability to mitigate or avoid the hazardous events. | G68: No | I68: Functional safety concept in latest version | J68: Review report of the functional safety concept
A71: 4 | B71: ISO 26262-4 | C71: Product development at the system level
B72: ISO 26262-4 Clause 5 | C72: Initiation of product development at the system level
A73: 4.1 | B73: ISO 26262-4, 5.5.2 | C73: Safety plan (refined) | D73: The safety activities for the product development at the system level shall be planned including determination of appropriate methods and measures during design and integration. The validation activities shall be planned. The functional safety assessment activities for the product development at the system level shall be planned. The tailoring of the lifecycle for product development at system level shall be performed in accordance with ISO 26262-2, and based on the reference phase model. NOTE The project plan can be used to provide the relationship between the individual subphases of product development at the system level and the hardware and software development phases. This can include the integration stECU at each level. | G73: No | I73: Safety plan (see No. 2.4) | J73: Safety plan (refined)
A76: 4.2 | B76: ISO 26262-4, 5.5.3 | C76: Item integration and testing plan | D76: Objective acc. the standard ISO 26262-4: The objective of the initiation of the product development at the system level is to determine and plan the functional safety activities during the individual sub phases of system development. This also includes the necessary supporting processes described in ISO 26262-8. This planning of system-level safety activities will be included in the safety plan. | G76: No | I76: Functional safety concept, Safety plan, Project plan | J76: Item integration and testing plan
...

Sheet Description of 3_Document_list
B1: =Cover!B1 -> Safety Plan
A2: 1.Description to headlines of sheet "3_Document_list"
A3: Part | B3: Refering part of ISO26262
A4: ISO 26262:2018 Work Products | B4: Name of the work products
A6: Reference to Safety Plan | B6: The reference number to the data sheet 2_Safety_plan
A7: initial/ refined | B7: "Initial": Is the first version of a work product. In a real progress of a project the available information is not as datailed as at the end of a project which has to lead to a refinement of a document. "Refined": shows that a certain stage of a project a document with the appropriate information should already be available. "Refined" usually means in the corresponding phase of the project additions for the appropriate work product.
A9: Link to external source | B9: Search link to an external Data base (e.g. Doors) where the document/the information is stored. There might be multiple links if there are more than one external sources be needed. This should be done by adding rows.
A10: Details to ext. Source | B10: There should be information added to locate the needed information. With reference to: "Link to external source"
A11: Index | B11: Actual Index of the Source if applicable.
A12: Title/chapter of comprised work product | B12: Titel (if reasonable: Chapter) of the work product.
A13: Todo's and Remarks | B13: Short description to open issues and global remarks or aspects Intention is to comment the next column "Status".
A14: Status | B14: "Actual status of the issue Description of Status, see Table ""Description of Status"""
A15: Date of Status | B15: Date of given status
A16: Responsible person: RASIC | B16: Definition see RASIC table below.
... A20: Date sent | B20: Date when the exchange was done.
A21: 2. Description of "RASIC"
A22: RASIC symbol | B22: Meaning | C22: Definition
A23: R | B23: Responsible | C23: Those who do the work to achieve the task. There is typically one role with a participation type of responsible, although others can be delegated to assist in the work required
A24: A | B24: Approver | C24: The one ultimately answerable for the correct and thorough completion of the deliverable or task, and the one who delegates the work to those responsible. In other words, an accountable must sign off (approve) on work that responsible provides.
A26: S | B26: Support | C26: Resources allocated to responsible. Unlike consulted, who may provide input to the task, support will assist in completing the task.
A27: I | B27: Informed | C27: Those who are kept up-to-date on progress, often only on completion of the task or deliverable; and with whom there is just one-way communication
A28: C | B28: Consulted | C28: Those whose opinions are sought, typically subject matter experts; and with whom there is two-way communication.
A29: 3. Sample use status
A30: Sample | B30: Meaning
A31: A-Sample | B31: The A-Sample shall be used for the presentation of  Concepts  Critical functions  Technology assessments  the sample is only for restricted use
A32: B-Sample | B32: The B-Samples are  Develop samples for technology-critical details, such as function, design, and assembly.  Samples used to uncover emergent product requirements  the samples may have use restrictions
A33: C-Sample | B33: The C-Samples are samples provide further test, development, and validation and are near-series samples. The C-Samples fulfill all specified safety and non-safety requirements. The Sample have no use restrictions.
A34: Initial Sample | B34: The initial sample is the first production falling part that was manufactured ​​on the final production plant.

Sheet Tabelle1
A1: Status
A2: open
A3: in progress
A4: in review
A5: reviewed
A6: approved
A7: released
A8: not applicable
